[2024-06-15T21:59:41.585+0000] {local_task_job_runner.py:120} INFO - ::group::Pre task execution logs
[2024-06-15T21:59:41.606+0000] {taskinstance.py:2076} INFO - Dependencies all met for dep_context=non-requeueable deps ti=<TaskInstance: process_sales_python_dag.copy_to_gcs_task manual__2022-08-09T18:07:09+00:00 [queued]>
[2024-06-15T21:59:41.617+0000] {taskinstance.py:2076} INFO - Dependencies all met for dep_context=requeueable deps ti=<TaskInstance: process_sales_python_dag.copy_to_gcs_task manual__2022-08-09T18:07:09+00:00 [queued]>
[2024-06-15T21:59:41.618+0000] {taskinstance.py:2306} INFO - Starting attempt 5 of 5
[2024-06-15T21:59:41.635+0000] {taskinstance.py:2330} INFO - Executing <Task(LocalFilesystemToGCSOperator): copy_to_gcs_task> on 2022-08-09 18:07:09+00:00
[2024-06-15T21:59:41.641+0000] {warnings.py:110} WARNING - /home/***/.local/lib/python3.12/site-packages/***/task/task_runner/standard_task_runner.py:61: DeprecationWarning: This process (pid=1443) is multi-threaded, use of fork() may lead to deadlocks in the child.
  pid = os.fork()

[2024-06-15T21:59:41.643+0000] {standard_task_runner.py:63} INFO - Started process 1459 to run task
[2024-06-15T21:59:41.643+0000] {standard_task_runner.py:90} INFO - Running: ['***', 'tasks', 'run', 'process_sales_python_dag', 'copy_to_gcs_task', 'manual__2022-08-09T18:07:09+00:00', '--job-id', '335', '--raw', '--subdir', 'DAGS_FOLDER/gcp_sales_load.py', '--cfg-path', '/tmp/tmpk12joh46']
[2024-06-15T21:59:41.647+0000] {standard_task_runner.py:91} INFO - Job 335: Subtask copy_to_gcs_task
[2024-06-15T21:59:41.700+0000] {task_command.py:426} INFO - Running <TaskInstance: process_sales_python_dag.copy_to_gcs_task manual__2022-08-09T18:07:09+00:00 [running]> on host 37ab05bbda86
[2024-06-15T21:59:41.852+0000] {taskinstance.py:2648} INFO - Exporting env vars: AIRFLOW_CTX_DAG_OWNER='***' AIRFLOW_CTX_DAG_ID='process_sales_python_dag' AIRFLOW_CTX_TASK_ID='copy_to_gcs_task' AIRFLOW_CTX_EXECUTION_DATE='2022-08-09T18:07:09+00:00' AIRFLOW_CTX_TRY_NUMBER='5' AIRFLOW_CTX_DAG_RUN_ID='manual__2022-08-09T18:07:09+00:00'
[2024-06-15T21:59:41.854+0000] {taskinstance.py:430} INFO - ::endgroup::
[2024-06-15T21:59:41.864+0000] {connection.py:274} WARNING - Connection schemes (type: google_cloud_platform) shall not contain '_' according to RFC3986.
[2024-06-15T21:59:41.868+0000] {base.py:84} INFO - Using connection ID 'google_cloud_default' for task execution.
[2024-06-15T21:59:41.919+0000] {taskinstance.py:441} INFO - ::group::Post task execution logs
[2024-06-15T21:59:41.920+0000] {taskinstance.py:2905} ERROR - Task failed with exception
Traceback (most recent call last):
  File "/home/airflow/.local/lib/python3.12/site-packages/airflow/models/taskinstance.py", line 465, in _execute_task
    result = _execute_callable(context=context, **execute_callable_kwargs)
             ^^^^^^^^^^^^^^^^^^^^^^^^^^^^^^^^^^^^^^^^^^^^^^^^^^^^^^^^^^^^^
  File "/home/airflow/.local/lib/python3.12/site-packages/airflow/models/taskinstance.py", line 432, in _execute_callable
    return execute_callable(context=context, **execute_callable_kwargs)
           ^^^^^^^^^^^^^^^^^^^^^^^^^^^^^^^^^^^^^^^^^^^^^^^^^^^^^^^^^^^^
  File "/home/airflow/.local/lib/python3.12/site-packages/airflow/models/baseoperator.py", line 400, in wrapper
    return func(self, *args, **kwargs)
           ^^^^^^^^^^^^^^^^^^^^^^^^^^^
  File "/home/airflow/.local/lib/python3.12/site-packages/airflow/providers/google/cloud/transfers/local_to_gcs.py", line 111, in execute
    hook.upload(
  File "/home/airflow/.local/lib/python3.12/site-packages/airflow/providers/google/cloud/hooks/gcs.py", line 550, in upload
    _call_with_retry(
  File "/home/airflow/.local/lib/python3.12/site-packages/airflow/providers/google/cloud/hooks/gcs.py", line 508, in _call_with_retry
    f()
  File "/home/airflow/.local/lib/python3.12/site-packages/google/cloud/storage/blob.py", line 2959, in upload_from_filename
    self._handle_filename_and_upload(
  File "/home/airflow/.local/lib/python3.12/site-packages/google/cloud/storage/blob.py", line 2827, in _handle_filename_and_upload
    with open(filename, "rb") as file_obj:
         ^^^^^^^^^^^^^^^^^^^^
IsADirectoryError: [Errno 21] Is a directory: '/opt/airflow/file_storage/stg/sales/2022-08-09/'
[2024-06-15T21:59:41.931+0000] {taskinstance.py:1206} INFO - Marking task as FAILED. dag_id=process_sales_python_dag, task_id=copy_to_gcs_task, run_id=manual__2022-08-09T18:07:09+00:00, execution_date=20220809T180709, start_date=20240615T215941, end_date=20240615T215941
[2024-06-15T21:59:41.945+0000] {standard_task_runner.py:110} ERROR - Failed to execute job 335 for task copy_to_gcs_task ([Errno 21] Is a directory: '/opt/airflow/file_storage/stg/sales/2022-08-09/'; 1459)
[2024-06-15T21:59:41.979+0000] {local_task_job_runner.py:240} INFO - Task exited with return code 1
[2024-06-15T21:59:42.025+0000] {taskinstance.py:3498} INFO - 0 downstream tasks scheduled from follow-on schedule check
[2024-06-15T21:59:42.032+0000] {local_task_job_runner.py:222} INFO - ::endgroup::
