[2024-06-15T21:56:21.788+0000] {local_task_job_runner.py:120} INFO - ::group::Pre task execution logs
[2024-06-15T21:56:21.807+0000] {taskinstance.py:2076} INFO - Dependencies all met for dep_context=non-requeueable deps ti=<TaskInstance: process_sales_python_dag.copy_to_gcs_task manual__2022-08-09T18:07:09+00:00 [queued]>
[2024-06-15T21:56:21.817+0000] {taskinstance.py:2076} INFO - Dependencies all met for dep_context=requeueable deps ti=<TaskInstance: process_sales_python_dag.copy_to_gcs_task manual__2022-08-09T18:07:09+00:00 [queued]>
[2024-06-15T21:56:21.818+0000] {taskinstance.py:2306} INFO - Starting attempt 3 of 3
[2024-06-15T21:56:21.839+0000] {taskinstance.py:2330} INFO - Executing <Task(LocalFilesystemToGCSOperator): copy_to_gcs_task> on 2022-08-09 18:07:09+00:00
[2024-06-15T21:56:21.850+0000] {warnings.py:110} WARNING - /home/***/.local/lib/python3.12/site-packages/***/task/task_runner/standard_task_runner.py:61: DeprecationWarning: This process (pid=83) is multi-threaded, use of fork() may lead to deadlocks in the child.
  pid = os.fork()

[2024-06-15T21:56:21.852+0000] {standard_task_runner.py:63} INFO - Started process 92 to run task
[2024-06-15T21:56:21.851+0000] {standard_task_runner.py:90} INFO - Running: ['***', 'tasks', 'run', 'process_sales_python_dag', 'copy_to_gcs_task', 'manual__2022-08-09T18:07:09+00:00', '--job-id', '332', '--raw', '--subdir', 'DAGS_FOLDER/gcp_sales_load.py', '--cfg-path', '/tmp/tmpoc7ljt2b']
[2024-06-15T21:56:21.854+0000] {standard_task_runner.py:91} INFO - Job 332: Subtask copy_to_gcs_task
[2024-06-15T21:56:21.913+0000] {task_command.py:426} INFO - Running <TaskInstance: process_sales_python_dag.copy_to_gcs_task manual__2022-08-09T18:07:09+00:00 [running]> on host 37ab05bbda86
[2024-06-15T21:56:22.019+0000] {taskinstance.py:2648} INFO - Exporting env vars: AIRFLOW_CTX_DAG_OWNER='***' AIRFLOW_CTX_DAG_ID='process_sales_python_dag' AIRFLOW_CTX_TASK_ID='copy_to_gcs_task' AIRFLOW_CTX_EXECUTION_DATE='2022-08-09T18:07:09+00:00' AIRFLOW_CTX_TRY_NUMBER='3' AIRFLOW_CTX_DAG_RUN_ID='manual__2022-08-09T18:07:09+00:00'
[2024-06-15T21:56:22.021+0000] {taskinstance.py:430} INFO - ::endgroup::
[2024-06-15T21:56:22.030+0000] {connection.py:274} WARNING - Connection schemes (type: google_cloud_platform) shall not contain '_' according to RFC3986.
[2024-06-15T21:56:22.032+0000] {base.py:84} INFO - Using connection ID 'google_cloud_default' for task execution.
[2024-06-15T21:56:22.036+0000] {credentials_provider.py:353} INFO - Getting connection using `google.auth.default()` since no explicit credentials are provided.
[2024-06-15T21:56:22.040+0000] {_metadata.py:139} WARNING - Compute Engine Metadata server unavailable on attempt 1 of 3. Reason: [Errno 111] Connection refused
[2024-06-15T21:56:22.043+0000] {_metadata.py:139} WARNING - Compute Engine Metadata server unavailable on attempt 2 of 3. Reason: [Errno 111] Connection refused
[2024-06-15T21:56:22.046+0000] {_metadata.py:139} WARNING - Compute Engine Metadata server unavailable on attempt 3 of 3. Reason: [Errno 111] Connection refused
[2024-06-15T21:56:22.047+0000] {_default.py:338} WARNING - Authentication failed using Compute Engine authentication due to unavailable metadata server.
[2024-06-15T21:56:22.048+0000] {taskinstance.py:441} INFO - ::group::Post task execution logs
[2024-06-15T21:56:22.049+0000] {taskinstance.py:2905} ERROR - Task failed with exception
Traceback (most recent call last):
  File "/home/airflow/.local/lib/python3.12/site-packages/airflow/models/taskinstance.py", line 465, in _execute_task
    result = _execute_callable(context=context, **execute_callable_kwargs)
             ^^^^^^^^^^^^^^^^^^^^^^^^^^^^^^^^^^^^^^^^^^^^^^^^^^^^^^^^^^^^^
  File "/home/airflow/.local/lib/python3.12/site-packages/airflow/models/taskinstance.py", line 432, in _execute_callable
    return execute_callable(context=context, **execute_callable_kwargs)
           ^^^^^^^^^^^^^^^^^^^^^^^^^^^^^^^^^^^^^^^^^^^^^^^^^^^^^^^^^^^^
  File "/home/airflow/.local/lib/python3.12/site-packages/airflow/models/baseoperator.py", line 400, in wrapper
    return func(self, *args, **kwargs)
           ^^^^^^^^^^^^^^^^^^^^^^^^^^^
  File "/home/airflow/.local/lib/python3.12/site-packages/airflow/providers/google/cloud/transfers/local_to_gcs.py", line 111, in execute
    hook.upload(
  File "/home/airflow/.local/lib/python3.12/site-packages/airflow/providers/google/cloud/hooks/gcs.py", line 524, in upload
    client = self.get_conn()
             ^^^^^^^^^^^^^^^
  File "/home/airflow/.local/lib/python3.12/site-packages/airflow/providers/google/cloud/hooks/gcs.py", line 169, in get_conn
    credentials=self.get_credentials(), client_info=CLIENT_INFO, project=self.project_id
                ^^^^^^^^^^^^^^^^^^^^^^
  File "/home/airflow/.local/lib/python3.12/site-packages/airflow/providers/google/common/hooks/base_google.py", line 308, in get_credentials
    credentials, _ = self.get_credentials_and_project_id()
                     ^^^^^^^^^^^^^^^^^^^^^^^^^^^^^^^^^^^^^
  File "/home/airflow/.local/lib/python3.12/site-packages/airflow/providers/google/common/hooks/base_google.py", line 285, in get_credentials_and_project_id
    credentials, project_id = get_credentials_and_project_id(
                              ^^^^^^^^^^^^^^^^^^^^^^^^^^^^^^^
  File "/home/airflow/.local/lib/python3.12/site-packages/airflow/providers/google/cloud/utils/credentials_provider.py", line 362, in get_credentials_and_project_id
    return _CredentialProvider(*args, **kwargs).get_credentials_and_project()
           ^^^^^^^^^^^^^^^^^^^^^^^^^^^^^^^^^^^^^^^^^^^^^^^^^^^^^^^^^^^^^^^^^^
  File "/home/airflow/.local/lib/python3.12/site-packages/airflow/providers/google/cloud/utils/credentials_provider.py", line 243, in get_credentials_and_project
    credentials, project_id = self._get_credentials_using_adc()
                              ^^^^^^^^^^^^^^^^^^^^^^^^^^^^^^^^^
  File "/home/airflow/.local/lib/python3.12/site-packages/airflow/providers/google/cloud/utils/credentials_provider.py", line 348, in _get_credentials_using_adc
    credentials, project_id = google.auth.default(scopes=self.scopes)
                              ^^^^^^^^^^^^^^^^^^^^^^^^^^^^^^^^^^^^^^^
  File "/home/airflow/.local/lib/python3.12/site-packages/google/auth/_default.py", line 691, in default
    raise exceptions.DefaultCredentialsError(_CLOUD_SDK_MISSING_CREDENTIALS)
google.auth.exceptions.DefaultCredentialsError: Your default credentials were not found. To set up Application Default Credentials, see https://cloud.google.com/docs/authentication/external/set-up-adc for more information.
[2024-06-15T21:56:22.060+0000] {taskinstance.py:1206} INFO - Marking task as FAILED. dag_id=process_sales_python_dag, task_id=copy_to_gcs_task, run_id=manual__2022-08-09T18:07:09+00:00, execution_date=20220809T180709, start_date=20240615T215621, end_date=20240615T215622
[2024-06-15T21:56:22.088+0000] {standard_task_runner.py:110} ERROR - Failed to execute job 332 for task copy_to_gcs_task (Your default credentials were not found. To set up Application Default Credentials, see https://cloud.google.com/docs/authentication/external/set-up-adc for more information.; 92)
[2024-06-15T21:56:22.107+0000] {local_task_job_runner.py:240} INFO - Task exited with return code 1
[2024-06-15T21:56:22.127+0000] {taskinstance.py:3498} INFO - 0 downstream tasks scheduled from follow-on schedule check
[2024-06-15T21:56:22.130+0000] {local_task_job_runner.py:222} INFO - ::endgroup::
